[33m[W 2025-05-13 19:37:07,585][0m Trial 0 failed with parameters: {'lr': 0.00010968135897761278, 'weight_decay': 1.6068930163566196e-05, 'batch_size': 32, 'n_layers': 4, 'hidden_dim': 512} because of the following error: KeyboardInterrupt().[0m
[Epoch 1/10] train_loss=0.8636 | val_loss=0.7404
Traceback (most recent call last):
  File "/home/panda/miniconda3/lib/python3.12/site-packages/optuna/study/_optimize.py", line 197, in _run_trial
    value_or_values = func(trial)
                      ^^^^^^^^^^^
  File "/home/panda/Soccer/train.py", line 484, in <lambda>
    lambda t: _objective(t, train_paths, val_paths, epochs, target_type,device),
              ^^^^^^^^^^^^^^^^^^^^^^^^^^^^^^^^^^^^^^^^^^^^^^^^^^^^^^^^^^^^^^^^^
  File "/home/panda/Soccer/train.py", line 470, in _objective
    trainer.train()
  File "/home/panda/Soccer/train.py", line 402, in train
    tr_loss = self._epoch(self.train_loader, True)
              ^^^^^^^^^^^^^^^^^^^^^^^^^^^^^^^^^^^^
  File "/home/panda/Soccer/train.py", line 372, in _epoch
    for batch_raw in pbar:
                     ^^^^
  File "/home/panda/miniconda3/lib/python3.12/site-packages/tqdm/std.py", line 1181, in __iter__
    for obj in iterable:
  File "/home/panda/miniconda3/lib/python3.12/site-packages/torch/utils/data/dataloader.py", line 733, in __next__
    data = self._next_data()
           ^^^^^^^^^^^^^^^^^
  File "/home/panda/miniconda3/lib/python3.12/site-packages/torch/utils/data/dataloader.py", line 1491, in _next_data
    idx, data = self._get_data()
                ^^^^^^^^^^^^^^^^
  File "/home/panda/miniconda3/lib/python3.12/site-packages/torch/utils/data/dataloader.py", line 1443, in _get_data
    success, data = self._try_get_data()
                    ^^^^^^^^^^^^^^^^^^^^
  File "/home/panda/miniconda3/lib/python3.12/site-packages/torch/utils/data/dataloader.py", line 1284, in _try_get_data
    data = self._data_queue.get(timeout=timeout)
           ^^^^^^^^^^^^^^^^^^^^^^^^^^^^^^^^^^^^^
  File "/home/panda/miniconda3/lib/python3.12/queue.py", line 180, in get
    self.not_empty.wait(remaining)
  File "/home/panda/miniconda3/lib/python3.12/threading.py", line 359, in wait
    gotit = waiter.acquire(True, timeout)
            ^^^^^^^^^^^^^^^^^^^^^^^^^^^^^
KeyboardInterrupt
[33m[W 2025-05-13 19:37:07,588][0m Trial 0 failed with value None.[0m
Traceback (most recent call last):
  File "/home/panda/Soccer/train.py", line 511, in <module>
    run_optuna(args.shards, args.trials, args.epochs, args.target, args.device)
  File "/home/panda/Soccer/train.py", line 483, in run_optuna
    study.optimize(
  File "/home/panda/miniconda3/lib/python3.12/site-packages/optuna/study/study.py", line 475, in optimize
    _optimize(
  File "/home/panda/miniconda3/lib/python3.12/site-packages/optuna/study/_optimize.py", line 63, in _optimize
    _optimize_sequential(
  File "/home/panda/miniconda3/lib/python3.12/site-packages/optuna/study/_optimize.py", line 160, in _optimize_sequential
    frozen_trial = _run_trial(study, func, catch)
                   ^^^^^^^^^^^^^^^^^^^^^^^^^^^^^^
  File "/home/panda/miniconda3/lib/python3.12/site-packages/optuna/study/_optimize.py", line 248, in _run_trial
    raise func_err
  File "/home/panda/miniconda3/lib/python3.12/site-packages/optuna/study/_optimize.py", line 197, in _run_trial
    value_or_values = func(trial)
                      ^^^^^^^^^^^
  File "/home/panda/Soccer/train.py", line 484, in <lambda>
    lambda t: _objective(t, train_paths, val_paths, epochs, target_type,device),
              ^^^^^^^^^^^^^^^^^^^^^^^^^^^^^^^^^^^^^^^^^^^^^^^^^^^^^^^^^^^^^^^^^
  File "/home/panda/Soccer/train.py", line 470, in _objective
    trainer.train()
  File "/home/panda/Soccer/train.py", line 402, in train
    tr_loss = self._epoch(self.train_loader, True)
              ^^^^^^^^^^^^^^^^^^^^^^^^^^^^^^^^^^^^
  File "/home/panda/Soccer/train.py", line 372, in _epoch
    for batch_raw in pbar:
                     ^^^^
  File "/home/panda/miniconda3/lib/python3.12/site-packages/tqdm/std.py", line 1181, in __iter__
    for obj in iterable:
  File "/home/panda/miniconda3/lib/python3.12/site-packages/torch/utils/data/dataloader.py", line 733, in __next__
    data = self._next_data()
           ^^^^^^^^^^^^^^^^^
  File "/home/panda/miniconda3/lib/python3.12/site-packages/torch/utils/data/dataloader.py", line 1491, in _next_data
    idx, data = self._get_data()
                ^^^^^^^^^^^^^^^^
  File "/home/panda/miniconda3/lib/python3.12/site-packages/torch/utils/data/dataloader.py", line 1443, in _get_data
    success, data = self._try_get_data()
                    ^^^^^^^^^^^^^^^^^^^^
  File "/home/panda/miniconda3/lib/python3.12/site-packages/torch/utils/data/dataloader.py", line 1284, in _try_get_data
    data = self._data_queue.get(timeout=timeout)
           ^^^^^^^^^^^^^^^^^^^^^^^^^^^^^^^^^^^^^
  File "/home/panda/miniconda3/lib/python3.12/queue.py", line 180, in get
    self.not_empty.wait(remaining)
  File "/home/panda/miniconda3/lib/python3.12/threading.py", line 359, in wait
    gotit = waiter.acquire(True, timeout)
            ^^^^^^^^^^^^^^^^^^^^^^^^^^^^^
KeyboardInterrupt
Exception ignored in atexit callback: <function _MultiProcessingDataLoaderIter._clean_up_worker at 0x7ae9dbd825c0>
Traceback (most recent call last):
  File "/home/panda/miniconda3/lib/python3.12/site-packages/torch/utils/data/dataloader.py", line 1657, in _clean_up_worker
    w.join(timeout=_utils.MP_STATUS_CHECK_INTERVAL)
  File "/home/panda/miniconda3/lib/python3.12/multiprocessing/process.py", line 149, in join
    res = self._popen.wait(timeout)
          ^^^^^^^^^^^^^^^^^^^^^^^^^
  File "/home/panda/miniconda3/lib/python3.12/multiprocessing/popen_fork.py", line 40, in wait
    if not wait([self.sentinel], timeout):
           ^^^^^^^^^^^^^^^^^^^^^^^^^^^^^^
  File "/home/panda/miniconda3/lib/python3.12/multiprocessing/connection.py", line 1136, in wait
    ready = selector.select(timeout)
            ^^^^^^^^^^^^^^^^^^^^^^^^
  File "/home/panda/miniconda3/lib/python3.12/selectors.py", line 415, in select
    fd_event_list = self._selector.poll(timeout)
                    ^^^^^^^^^^^^^^^^^^^^^^^^^^^^
KeyboardInterrupt:
Exception ignored in atexit callback: <function _MultiProcessingDataLoaderIter._clean_up_worker at 0x7ae9dbd825c0>
Traceback (most recent call last):
  File "/home/panda/miniconda3/lib/python3.12/site-packages/torch/utils/data/dataloader.py", line 1657, in _clean_up_worker
    w.join(timeout=_utils.MP_STATUS_CHECK_INTERVAL)
  File "/home/panda/miniconda3/lib/python3.12/multiprocessing/process.py", line 149, in join
    res = self._popen.wait(timeout)
          ^^^^^^^^^^^^^^^^^^^^^^^^^
  File "/home/panda/miniconda3/lib/python3.12/multiprocessing/popen_fork.py", line 40, in wait
    if not wait([self.sentinel], timeout):
           ^^^^^^^^^^^^^^^^^^^^^^^^^^^^^^
  File "/home/panda/miniconda3/lib/python3.12/multiprocessing/connection.py", line 1136, in wait
    ready = selector.select(timeout)
            ^^^^^^^^^^^^^^^^^^^^^^^^
  File "/home/panda/miniconda3/lib/python3.12/selectors.py", line 415, in select
    fd_event_list = self._selector.poll(timeout)
                    ^^^^^^^^^^^^^^^^^^^^^^^^^^^^
  File "/home/panda/miniconda3/lib/python3.12/site-packages/torch/utils/data/_utils/signal_handling.py", line 73, in handler
    _error_if_any_worker_fails()
RuntimeError: DataLoader worker (pid 2186502) exited unexpectedly with exit code 1. Details are lost due to multiprocessing. Rerunning with num_workers=0 may give better error trace.
