[33m[W 2025-05-13 18:35:47,648][0m Trial 0 failed with parameters: {'lr': 4.6063509766865834e-05, 'weight_decay': 5.245705221728329e-06, 'batch_size': 64, 'n_layers': 3, 'hidden_dim': 1024} because of the following error: KeyboardInterrupt().[0m
[Epoch 1/5] train_loss=14.1493 | val_loss=12.8696
[Epoch 2/5] train_loss=13.8390 | val_loss=13.2606
[Epoch 3/5] train_loss=13.5921 | val_loss=13.2789
[Epoch 4/5] train_loss=13.2542 | val_loss=13.9058
Traceback (most recent call last):
  File "/home/panda/miniconda3/lib/python3.12/site-packages/optuna/study/_optimize.py", line 197, in _run_trial
    value_or_values = func(trial)
                      ^^^^^^^^^^^
  File "/home/panda/Soccer/train.py", line 470, in <lambda>
    lambda t: _objective(t, train_paths, val_paths, epochs, target_type),
              ^^^^^^^^^^^^^^^^^^^^^^^^^^^^^^^^^^^^^^^^^^^^^^^^^^^^^^^^^^
  File "/home/panda/Soccer/train.py", line 462, in _objective
    trainer.train()
  File "/home/panda/Soccer/train.py", line 395, in train
    tr_loss = self._epoch(self.train_loader, True)
              ^^^^^^^^^^^^^^^^^^^^^^^^^^^^^^^^^^^^
  File "/home/panda/Soccer/train.py", line 366, in _epoch
    for batch_raw in pbar:
                     ^^^^
  File "/home/panda/miniconda3/lib/python3.12/site-packages/tqdm/std.py", line 1181, in __iter__
    for obj in iterable:
  File "/home/panda/miniconda3/lib/python3.12/site-packages/torch/utils/data/dataloader.py", line 733, in __next__
    data = self._next_data()
           ^^^^^^^^^^^^^^^^^
  File "/home/panda/miniconda3/lib/python3.12/site-packages/torch/utils/data/dataloader.py", line 1491, in _next_data
    idx, data = self._get_data()
                ^^^^^^^^^^^^^^^^
  File "/home/panda/miniconda3/lib/python3.12/site-packages/torch/utils/data/dataloader.py", line 1443, in _get_data
    success, data = self._try_get_data()
                    ^^^^^^^^^^^^^^^^^^^^
  File "/home/panda/miniconda3/lib/python3.12/site-packages/torch/utils/data/dataloader.py", line 1284, in _try_get_data
    data = self._data_queue.get(timeout=timeout)
           ^^^^^^^^^^^^^^^^^^^^^^^^^^^^^^^^^^^^^
  File "/home/panda/miniconda3/lib/python3.12/queue.py", line 180, in get
    self.not_empty.wait(remaining)
  File "/home/panda/miniconda3/lib/python3.12/threading.py", line 359, in wait
    gotit = waiter.acquire(True, timeout)
            ^^^^^^^^^^^^^^^^^^^^^^^^^^^^^
KeyboardInterrupt
[33m[W 2025-05-13 18:35:47,657][0m Trial 0 failed with value None.[0m
Traceback (most recent call last):
  File "/home/panda/Soccer/train.py", line 495, in <module>
    run_optuna(args.shards, args.trials, args.epochs, args.target)
  File "/home/panda/Soccer/train.py", line 469, in run_optuna
    study.optimize(
  File "/home/panda/miniconda3/lib/python3.12/site-packages/optuna/study/study.py", line 475, in optimize
    _optimize(
  File "/home/panda/miniconda3/lib/python3.12/site-packages/optuna/study/_optimize.py", line 63, in _optimize
    _optimize_sequential(
  File "/home/panda/miniconda3/lib/python3.12/site-packages/optuna/study/_optimize.py", line 160, in _optimize_sequential
    frozen_trial = _run_trial(study, func, catch)
                   ^^^^^^^^^^^^^^^^^^^^^^^^^^^^^^
  File "/home/panda/miniconda3/lib/python3.12/site-packages/optuna/study/_optimize.py", line 248, in _run_trial
    raise func_err
  File "/home/panda/miniconda3/lib/python3.12/site-packages/optuna/study/_optimize.py", line 197, in _run_trial
    value_or_values = func(trial)
                      ^^^^^^^^^^^
  File "/home/panda/Soccer/train.py", line 470, in <lambda>
    lambda t: _objective(t, train_paths, val_paths, epochs, target_type),
              ^^^^^^^^^^^^^^^^^^^^^^^^^^^^^^^^^^^^^^^^^^^^^^^^^^^^^^^^^^
  File "/home/panda/Soccer/train.py", line 462, in _objective
    trainer.train()
  File "/home/panda/Soccer/train.py", line 395, in train
    tr_loss = self._epoch(self.train_loader, True)
              ^^^^^^^^^^^^^^^^^^^^^^^^^^^^^^^^^^^^
  File "/home/panda/Soccer/train.py", line 366, in _epoch
    for batch_raw in pbar:
                     ^^^^
  File "/home/panda/miniconda3/lib/python3.12/site-packages/tqdm/std.py", line 1181, in __iter__
    for obj in iterable:
  File "/home/panda/miniconda3/lib/python3.12/site-packages/torch/utils/data/dataloader.py", line 733, in __next__
    data = self._next_data()
           ^^^^^^^^^^^^^^^^^
  File "/home/panda/miniconda3/lib/python3.12/site-packages/torch/utils/data/dataloader.py", line 1491, in _next_data
    idx, data = self._get_data()
                ^^^^^^^^^^^^^^^^
  File "/home/panda/miniconda3/lib/python3.12/site-packages/torch/utils/data/dataloader.py", line 1443, in _get_data
    success, data = self._try_get_data()
                    ^^^^^^^^^^^^^^^^^^^^
  File "/home/panda/miniconda3/lib/python3.12/site-packages/torch/utils/data/dataloader.py", line 1284, in _try_get_data
    data = self._data_queue.get(timeout=timeout)
           ^^^^^^^^^^^^^^^^^^^^^^^^^^^^^^^^^^^^^
  File "/home/panda/miniconda3/lib/python3.12/queue.py", line 180, in get
    self.not_empty.wait(remaining)
  File "/home/panda/miniconda3/lib/python3.12/threading.py", line 359, in wait
    gotit = waiter.acquire(True, timeout)
            ^^^^^^^^^^^^^^^^^^^^^^^^^^^^^
KeyboardInterrupt
Exception ignored in atexit callback: <function _MultiProcessingDataLoaderIter._clean_up_worker at 0x7b9933782700>
Traceback (most recent call last):
  File "/home/panda/miniconda3/lib/python3.12/site-packages/torch/utils/data/dataloader.py", line 1657, in _clean_up_worker
    w.join(timeout=_utils.MP_STATUS_CHECK_INTERVAL)
  File "/home/panda/miniconda3/lib/python3.12/multiprocessing/process.py", line 149, in join
    res = self._popen.wait(timeout)
          ^^^^^^^^^^^^^^^^^^^^^^^^^
  File "/home/panda/miniconda3/lib/python3.12/multiprocessing/popen_fork.py", line 40, in wait
    if not wait([self.sentinel], timeout):
           ^^^^^^^^^^^^^^^^^^^^^^^^^^^^^^
  File "/home/panda/miniconda3/lib/python3.12/multiprocessing/connection.py", line 1136, in wait
    ready = selector.select(timeout)
            ^^^^^^^^^^^^^^^^^^^^^^^^
  File "/home/panda/miniconda3/lib/python3.12/selectors.py", line 415, in select
    fd_event_list = self._selector.poll(timeout)
                    ^^^^^^^^^^^^^^^^^^^^^^^^^^^^
KeyboardInterrupt:
Exception in thread Thread-4 (_pin_memory_loop):
Traceback (most recent call last):
  File "/home/panda/miniconda3/lib/python3.12/threading.py", line 1075, in _bootstrap_inner
    self.run()
  File "/home/panda/miniconda3/lib/python3.12/threading.py", line 1012, in run
    self._target(*self._args, **self._kwargs)
  File "/home/panda/miniconda3/lib/python3.12/site-packages/torch/utils/data/_utils/pin_memory.py", line 61, in _pin_memory_loop
    do_one_step()
  File "/home/panda/miniconda3/lib/python3.12/site-packages/torch/utils/data/_utils/pin_memory.py", line 37, in do_one_step
    r = in_queue.get(timeout=MP_STATUS_CHECK_INTERVAL)
        ^^^^^^^^^^^^^^^^^^^^^^^^^^^^^^^^^^^^^^^^^^^^^^
  File "/home/panda/miniconda3/lib/python3.12/multiprocessing/queues.py", line 122, in get
    return _ForkingPickler.loads(res)
           ^^^^^^^^^^^^^^^^^^^^^^^^^^
  File "/home/panda/miniconda3/lib/python3.12/site-packages/torch/multiprocessing/reductions.py", line 541, in rebuild_storage_fd
    fd = df.detach()
         ^^^^^^^^^^^
  File "/home/panda/miniconda3/lib/python3.12/multiprocessing/resource_sharer.py", line 57, in detach
    with _resource_sharer.get_connection(self._id) as conn:
         ^^^^^^^^^^^^^^^^^^^^^^^^^^^^^^^^^^^^^^^^^
  File "/home/panda/miniconda3/lib/python3.12/multiprocessing/resource_sharer.py", line 86, in get_connection
    c = Client(address, authkey=process.current_process().authkey)
        ^^^^^^^^^^^^^^^^^^^^^^^^^^^^^^^^^^^^^^^^^^^^^^^^^^^^^^^^^^
  File "/home/panda/miniconda3/lib/python3.12/multiprocessing/connection.py", line 519, in Client
    c = SocketClient(address)
        ^^^^^^^^^^^^^^^^^^^^^
  File "/home/panda/miniconda3/lib/python3.12/multiprocessing/connection.py", line 647, in SocketClient
    s.connect(address)
FileNotFoundError: [Errno 2] No such file or directory
Exception ignored in atexit callback: <function _MultiProcessingDataLoaderIter._clean_up_worker at 0x7b9933782700>
Traceback (most recent call last):
  File "/home/panda/miniconda3/lib/python3.12/site-packages/torch/utils/data/dataloader.py", line 1657, in _clean_up_worker
    w.join(timeout=_utils.MP_STATUS_CHECK_INTERVAL)
  File "/home/panda/miniconda3/lib/python3.12/multiprocessing/process.py", line 149, in join
    res = self._popen.wait(timeout)
          ^^^^^^^^^^^^^^^^^^^^^^^^^
  File "/home/panda/miniconda3/lib/python3.12/multiprocessing/popen_fork.py", line 40, in wait
    if not wait([self.sentinel], timeout):
           ^^^^^^^^^^^^^^^^^^^^^^^^^^^^^^
  File "/home/panda/miniconda3/lib/python3.12/multiprocessing/connection.py", line 1136, in wait
    ready = selector.select(timeout)
            ^^^^^^^^^^^^^^^^^^^^^^^^
  File "/home/panda/miniconda3/lib/python3.12/selectors.py", line 415, in select
    fd_event_list = self._selector.poll(timeout)
                    ^^^^^^^^^^^^^^^^^^^^^^^^^^^^
  File "/home/panda/miniconda3/lib/python3.12/site-packages/torch/utils/data/_utils/signal_handling.py", line 73, in handler
    _error_if_any_worker_fails()
RuntimeError: DataLoader worker (pid 2078129) exited unexpectedly with exit code 1. Details are lost due to multiprocessing. Rerunning with num_workers=0 may give better error trace.
