[33m[W 2025-05-13 19:13:51,354][0m Trial 0 failed with parameters: {'lr': 9.634981230667342e-05, 'weight_decay': 0.004369623195926894, 'batch_size': 32, 'n_layers': 4, 'hidden_dim': 512} because of the following error: KeyboardInterrupt().[0m
[Epoch 1/5] train_loss=0.2675 | val_loss=0.2206
[Epoch 2/5] train_loss=0.2632 | val_loss=0.2212
[Epoch 3/5] train_loss=0.2620 | val_loss=0.2114
Traceback (most recent call last):
  File "/home/panda/miniconda3/lib/python3.12/site-packages/optuna/study/_optimize.py", line 197, in _run_trial
    value_or_values = func(trial)
                      ^^^^^^^^^^^
  File "/home/panda/Soccer/train.py", line 481, in <lambda>
    lambda t: _objective(t, train_paths, val_paths, epochs, target_type),
              ^^^^^^^^^^^^^^^^^^^^^^^^^^^^^^^^^^^^^^^^^^^^^^^^^^^^^^^^^^
  File "/home/panda/Soccer/train.py", line 467, in _objective
    trainer.train()
  File "/home/panda/Soccer/train.py", line 400, in train
    tr_loss = self._epoch(self.train_loader, True)
              ^^^^^^^^^^^^^^^^^^^^^^^^^^^^^^^^^^^^
  File "/home/panda/Soccer/train.py", line 382, in _epoch
    loss.backward()
  File "/home/panda/miniconda3/lib/python3.12/site-packages/torch/_tensor.py", line 648, in backward
    torch.autograd.backward(
  File "/home/panda/miniconda3/lib/python3.12/site-packages/torch/autograd/__init__.py", line 353, in backward
    _engine_run_backward(
  File "/home/panda/miniconda3/lib/python3.12/site-packages/torch/autograd/graph.py", line 824, in _engine_run_backward
    return Variable._execution_engine.run_backward(  # Calls into the C++ engine to run the backward pass
           ^^^^^^^^^^^^^^^^^^^^^^^^^^^^^^^^^^^^^^^^^^^^^^^^^^^^^^^^^^^^^^^^^^^^^^^^^^^^^^^^^^^^^^^^^^^^^^
KeyboardInterrupt
[33m[W 2025-05-13 19:13:51,355][0m Trial 0 failed with value None.[0m
Traceback (most recent call last):
  File "/home/panda/Soccer/train.py", line 507, in <module>
    run_optuna(args.shards, args.trials, args.epochs, args.target)
  File "/home/panda/Soccer/train.py", line 480, in run_optuna
    study.optimize(
  File "/home/panda/miniconda3/lib/python3.12/site-packages/optuna/study/study.py", line 475, in optimize
    _optimize(
  File "/home/panda/miniconda3/lib/python3.12/site-packages/optuna/study/_optimize.py", line 63, in _optimize
    _optimize_sequential(
  File "/home/panda/miniconda3/lib/python3.12/site-packages/optuna/study/_optimize.py", line 160, in _optimize_sequential
    frozen_trial = _run_trial(study, func, catch)
                   ^^^^^^^^^^^^^^^^^^^^^^^^^^^^^^
  File "/home/panda/miniconda3/lib/python3.12/site-packages/optuna/study/_optimize.py", line 248, in _run_trial
    raise func_err
  File "/home/panda/miniconda3/lib/python3.12/site-packages/optuna/study/_optimize.py", line 197, in _run_trial
    value_or_values = func(trial)
                      ^^^^^^^^^^^
  File "/home/panda/Soccer/train.py", line 481, in <lambda>
    lambda t: _objective(t, train_paths, val_paths, epochs, target_type),
              ^^^^^^^^^^^^^^^^^^^^^^^^^^^^^^^^^^^^^^^^^^^^^^^^^^^^^^^^^^
  File "/home/panda/Soccer/train.py", line 467, in _objective
    trainer.train()
  File "/home/panda/Soccer/train.py", line 400, in train
    tr_loss = self._epoch(self.train_loader, True)
              ^^^^^^^^^^^^^^^^^^^^^^^^^^^^^^^^^^^^
  File "/home/panda/Soccer/train.py", line 382, in _epoch
    loss.backward()
  File "/home/panda/miniconda3/lib/python3.12/site-packages/torch/_tensor.py", line 648, in backward
    torch.autograd.backward(
  File "/home/panda/miniconda3/lib/python3.12/site-packages/torch/autograd/__init__.py", line 353, in backward
    _engine_run_backward(
  File "/home/panda/miniconda3/lib/python3.12/site-packages/torch/autograd/graph.py", line 824, in _engine_run_backward
    return Variable._execution_engine.run_backward(  # Calls into the C++ engine to run the backward pass
           ^^^^^^^^^^^^^^^^^^^^^^^^^^^^^^^^^^^^^^^^^^^^^^^^^^^^^^^^^^^^^^^^^^^^^^^^^^^^^^^^^^^^^^^^^^^^^^
KeyboardInterrupt
Exception ignored in atexit callback: <function _MultiProcessingDataLoaderIter._clean_up_worker at 0x6ffff27867a0>
Traceback (most recent call last):
  File "/home/panda/miniconda3/lib/python3.12/site-packages/torch/utils/data/dataloader.py", line 1657, in _clean_up_worker
    w.join(timeout=_utils.MP_STATUS_CHECK_INTERVAL)
  File "/home/panda/miniconda3/lib/python3.12/multiprocessing/process.py", line 149, in join
    res = self._popen.wait(timeout)
          ^^^^^^^^^^^^^^^^^^^^^^^^^
  File "/home/panda/miniconda3/lib/python3.12/multiprocessing/popen_fork.py", line 40, in wait
    if not wait([self.sentinel], timeout):
           ^^^^^^^^^^^^^^^^^^^^^^^^^^^^^^
  File "/home/panda/miniconda3/lib/python3.12/multiprocessing/connection.py", line 1136, in wait
    ready = selector.select(timeout)
            ^^^^^^^^^^^^^^^^^^^^^^^^
  File "/home/panda/miniconda3/lib/python3.12/selectors.py", line 415, in select
    fd_event_list = self._selector.poll(timeout)
                    ^^^^^^^^^^^^^^^^^^^^^^^^^^^^
KeyboardInterrupt:
Exception ignored in atexit callback: <function _MultiProcessingDataLoaderIter._clean_up_worker at 0x6ffff27867a0>
Traceback (most recent call last):
  File "/home/panda/miniconda3/lib/python3.12/site-packages/torch/utils/data/dataloader.py", line 1657, in _clean_up_worker
    w.join(timeout=_utils.MP_STATUS_CHECK_INTERVAL)
  File "/home/panda/miniconda3/lib/python3.12/multiprocessing/process.py", line 149, in join
    res = self._popen.wait(timeout)
          ^^^^^^^^^^^^^^^^^^^^^^^^^
  File "/home/panda/miniconda3/lib/python3.12/multiprocessing/popen_fork.py", line 40, in wait
    if not wait([self.sentinel], timeout):
           ^^^^^^^^^^^^^^^^^^^^^^^^^^^^^^
  File "/home/panda/miniconda3/lib/python3.12/multiprocessing/connection.py", line 1136, in wait
    ready = selector.select(timeout)
            ^^^^^^^^^^^^^^^^^^^^^^^^
  File "/home/panda/miniconda3/lib/python3.12/selectors.py", line 415, in select
    fd_event_list = self._selector.poll(timeout)
                    ^^^^^^^^^^^^^^^^^^^^^^^^^^^^
  File "/home/panda/miniconda3/lib/python3.12/site-packages/torch/utils/data/_utils/signal_handling.py", line 73, in handler
    _error_if_any_worker_fails()
RuntimeError: DataLoader worker (pid 2164281) exited unexpectedly with exit code 1. Details are lost due to multiprocessing. Rerunning with num_workers=0 may give better error trace.
